[2024-07-08T10:26:27.605+0000] {local_task_job_runner.py:120} INFO - ::group::Pre task execution logs
[2024-07-08T10:26:27.622+0000] {taskinstance.py:2076} INFO - Dependencies all met for dep_context=non-requeueable deps ti=<TaskInstance: etl_latest_s3_to_snowflake.extract scheduled__2024-07-07T00:00:00+00:00 [queued]>
[2024-07-08T10:26:27.625+0000] {taskinstance.py:2076} INFO - Dependencies all met for dep_context=requeueable deps ti=<TaskInstance: etl_latest_s3_to_snowflake.extract scheduled__2024-07-07T00:00:00+00:00 [queued]>
[2024-07-08T10:26:27.626+0000] {taskinstance.py:2306} INFO - Starting attempt 1 of 1
[2024-07-08T10:26:27.632+0000] {taskinstance.py:2330} INFO - Executing <Task(PythonOperator): extract> on 2024-07-07 00:00:00+00:00
[2024-07-08T10:26:27.639+0000] {warnings.py:112} WARNING - /home/***/.local/lib/python3.12/site-packages/***/task/task_runner/standard_task_runner.py:61: DeprecationWarning: This process (pid=25578) is multi-threaded, use of fork() may lead to deadlocks in the child.
  pid = os.fork()

[2024-07-08T10:26:27.640+0000] {standard_task_runner.py:63} INFO - Started process 25587 to run task
[2024-07-08T10:26:27.640+0000] {standard_task_runner.py:90} INFO - Running: ['***', 'tasks', 'run', 'etl_latest_s3_to_snowflake', 'extract', 'scheduled__2024-07-07T00:00:00+00:00', '--job-id', '566', '--raw', '--subdir', 'DAGS_FOLDER/s3_snowflake.py', '--cfg-path', '/tmp/tmpnw83trun']
[2024-07-08T10:26:27.640+0000] {standard_task_runner.py:91} INFO - Job 566: Subtask extract
[2024-07-08T10:26:27.674+0000] {task_command.py:426} INFO - Running <TaskInstance: etl_latest_s3_to_snowflake.extract scheduled__2024-07-07T00:00:00+00:00 [running]> on host 887bcaddc0d8
[2024-07-08T10:26:27.740+0000] {taskinstance.py:2648} INFO - Exporting env vars: AIRFLOW_CTX_DAG_OWNER='***' AIRFLOW_CTX_DAG_ID='etl_latest_s3_to_snowflake' AIRFLOW_CTX_TASK_ID='extract' AIRFLOW_CTX_EXECUTION_DATE='2024-07-07T00:00:00+00:00' AIRFLOW_CTX_TRY_NUMBER='1' AIRFLOW_CTX_DAG_RUN_ID='scheduled__2024-07-07T00:00:00+00:00'
[2024-07-08T10:26:27.742+0000] {taskinstance.py:430} INFO - ::endgroup::
[2024-07-08T10:26:30.078+0000] {taskinstance.py:441} INFO - ::group::Post task execution logs
[2024-07-08T10:26:30.104+0000] {taskinstance.py:2905} ERROR - Task failed with exception
Traceback (most recent call last):
  File "/home/airflow/.local/lib/python3.12/site-packages/airflow/models/taskinstance.py", line 465, in _execute_task
    result = _execute_callable(context=context, **execute_callable_kwargs)
             ^^^^^^^^^^^^^^^^^^^^^^^^^^^^^^^^^^^^^^^^^^^^^^^^^^^^^^^^^^^^^
  File "/home/airflow/.local/lib/python3.12/site-packages/airflow/models/taskinstance.py", line 432, in _execute_callable
    return execute_callable(context=context, **execute_callable_kwargs)
           ^^^^^^^^^^^^^^^^^^^^^^^^^^^^^^^^^^^^^^^^^^^^^^^^^^^^^^^^^^^^
  File "/home/airflow/.local/lib/python3.12/site-packages/airflow/models/baseoperator.py", line 401, in wrapper
    return func(self, *args, **kwargs)
           ^^^^^^^^^^^^^^^^^^^^^^^^^^^
  File "/home/airflow/.local/lib/python3.12/site-packages/airflow/operators/python.py", line 235, in execute
    return_value = self.execute_callable()
                   ^^^^^^^^^^^^^^^^^^^^^^^
  File "/home/airflow/.local/lib/python3.12/site-packages/airflow/operators/python.py", line 252, in execute_callable
    return self.python_callable(*self.op_args, **self.op_kwargs)
           ^^^^^^^^^^^^^^^^^^^^^^^^^^^^^^^^^^^^^^^^^^^^^^^^^^^^^
  File "/opt/airflow/dags/s3_snowflake.py", line 32, in extract
    df, table_name = load_csv_to_df(s3_bucket, s3_prefix)
                     ^^^^^^^^^^^^^^^^^^^^^^^^^^^^^^^^^^^^
  File "/opt/airflow/dags/extract.py", line 17, in load_csv_to_df
    latest_file = get_latest_file(s3_bucket, s3_prefix)
                  ^^^^^^^^^^^^^^^^^^^^^^^^^^^^^^^^^^^^^
  File "/opt/airflow/dags/extract.py", line 7, in get_latest_file
    response = s3.list_objects_v2(Bucket=s3_bucket, Prefix=s3_prefix)
               ^^^^^^^^^^^^^^^^^^^^^^^^^^^^^^^^^^^^^^^^^^^^^^^^^^^^^^
  File "/home/airflow/.local/lib/python3.12/site-packages/botocore/client.py", line 565, in _api_call
    return self._make_api_call(operation_name, kwargs)
           ^^^^^^^^^^^^^^^^^^^^^^^^^^^^^^^^^^^^^^^^^^^
  File "/home/airflow/.local/lib/python3.12/site-packages/botocore/client.py", line 1001, in _make_api_call
    http, parsed_response = self._make_request(
                            ^^^^^^^^^^^^^^^^^^^
  File "/home/airflow/.local/lib/python3.12/site-packages/botocore/client.py", line 1027, in _make_request
    return self._endpoint.make_request(operation_model, request_dict)
           ^^^^^^^^^^^^^^^^^^^^^^^^^^^^^^^^^^^^^^^^^^^^^^^^^^^^^^^^^^
  File "/home/airflow/.local/lib/python3.12/site-packages/botocore/endpoint.py", line 119, in make_request
    return self._send_request(request_dict, operation_model)
           ^^^^^^^^^^^^^^^^^^^^^^^^^^^^^^^^^^^^^^^^^^^^^^^^^
  File "/home/airflow/.local/lib/python3.12/site-packages/botocore/endpoint.py", line 198, in _send_request
    request = self.create_request(request_dict, operation_model)
              ^^^^^^^^^^^^^^^^^^^^^^^^^^^^^^^^^^^^^^^^^^^^^^^^^^
  File "/home/airflow/.local/lib/python3.12/site-packages/botocore/endpoint.py", line 134, in create_request
    self._event_emitter.emit(
  File "/home/airflow/.local/lib/python3.12/site-packages/botocore/hooks.py", line 412, in emit
    return self._emitter.emit(aliased_event_name, **kwargs)
           ^^^^^^^^^^^^^^^^^^^^^^^^^^^^^^^^^^^^^^^^^^^^^^^^
  File "/home/airflow/.local/lib/python3.12/site-packages/botocore/hooks.py", line 256, in emit
    return self._emit(event_name, kwargs)
           ^^^^^^^^^^^^^^^^^^^^^^^^^^^^^^
  File "/home/airflow/.local/lib/python3.12/site-packages/botocore/hooks.py", line 239, in _emit
    response = handler(**kwargs)
               ^^^^^^^^^^^^^^^^^
  File "/home/airflow/.local/lib/python3.12/site-packages/botocore/signers.py", line 105, in handler
    return self.sign(operation_name, request)
           ^^^^^^^^^^^^^^^^^^^^^^^^^^^^^^^^^^
  File "/home/airflow/.local/lib/python3.12/site-packages/botocore/signers.py", line 199, in sign
    auth.add_auth(request)
  File "/home/airflow/.local/lib/python3.12/site-packages/botocore/auth.py", line 418, in add_auth
    raise NoCredentialsError()
botocore.exceptions.NoCredentialsError: Unable to locate credentials
[2024-07-08T10:26:30.171+0000] {taskinstance.py:1206} INFO - Marking task as FAILED. dag_id=etl_latest_s3_to_snowflake, task_id=extract, run_id=scheduled__2024-07-07T00:00:00+00:00, execution_date=20240707T000000, start_date=20240708T102627, end_date=20240708T102630
[2024-07-08T10:26:30.253+0000] {standard_task_runner.py:110} ERROR - Failed to execute job 566 for task extract (Unable to locate credentials; 25587)
[2024-07-08T10:26:30.315+0000] {local_task_job_runner.py:240} INFO - Task exited with return code 1
[2024-07-08T10:26:30.394+0000] {taskinstance.py:3503} INFO - 0 downstream tasks scheduled from follow-on schedule check
[2024-07-08T10:26:30.397+0000] {local_task_job_runner.py:222} INFO - ::endgroup::
