[2024-07-09T15:10:28.951+0000] {local_task_job_runner.py:120} INFO - ::group::Pre task execution logs
[2024-07-09T15:10:28.977+0000] {taskinstance.py:2076} INFO - Dependencies all met for dep_context=non-requeueable deps ti=<TaskInstance: etl_process.etl_products scheduled__2024-07-08T00:00:00+00:00 [queued]>
[2024-07-09T15:10:28.991+0000] {taskinstance.py:2076} INFO - Dependencies all met for dep_context=requeueable deps ti=<TaskInstance: etl_process.etl_products scheduled__2024-07-08T00:00:00+00:00 [queued]>
[2024-07-09T15:10:28.993+0000] {taskinstance.py:2306} INFO - Starting attempt 1 of 2
[2024-07-09T15:10:29.006+0000] {taskinstance.py:2330} INFO - Executing <Task(PythonOperator): etl_products> on 2024-07-08 00:00:00+00:00
[2024-07-09T15:10:29.012+0000] {warnings.py:112} WARNING - /home/***/.local/lib/python3.12/site-packages/***/task/task_runner/standard_task_runner.py:61: DeprecationWarning: This process (pid=85901) is multi-threaded, use of fork() may lead to deadlocks in the child.
  pid = os.fork()

[2024-07-09T15:10:29.014+0000] {standard_task_runner.py:63} INFO - Started process 85909 to run task
[2024-07-09T15:10:29.025+0000] {standard_task_runner.py:90} INFO - Running: ['***', 'tasks', 'run', 'etl_process', 'etl_products', 'scheduled__2024-07-08T00:00:00+00:00', '--job-id', '571', '--raw', '--subdir', 'DAGS_FOLDER/dag.py', '--cfg-path', '/tmp/tmp9zb_l_79']
[2024-07-09T15:10:29.027+0000] {standard_task_runner.py:91} INFO - Job 571: Subtask etl_products
[2024-07-09T15:10:29.144+0000] {task_command.py:426} INFO - Running <TaskInstance: etl_process.etl_products scheduled__2024-07-08T00:00:00+00:00 [running]> on host 887bcaddc0d8
[2024-07-09T15:10:29.245+0000] {taskinstance.py:2648} INFO - Exporting env vars: AIRFLOW_CTX_DAG_OWNER='***' AIRFLOW_CTX_DAG_ID='etl_process' AIRFLOW_CTX_TASK_ID='etl_products' AIRFLOW_CTX_EXECUTION_DATE='2024-07-08T00:00:00+00:00' AIRFLOW_CTX_TRY_NUMBER='1' AIRFLOW_CTX_DAG_RUN_ID='scheduled__2024-07-08T00:00:00+00:00'
[2024-07-09T15:10:29.250+0000] {taskinstance.py:430} INFO - ::endgroup::
[2024-07-09T15:10:31.756+0000] {taskinstance.py:441} INFO - ::group::Post task execution logs
[2024-07-09T15:10:31.762+0000] {taskinstance.py:2905} ERROR - Task failed with exception
Traceback (most recent call last):
  File "/home/airflow/.local/lib/python3.12/site-packages/airflow/models/taskinstance.py", line 465, in _execute_task
    result = _execute_callable(context=context, **execute_callable_kwargs)
             ^^^^^^^^^^^^^^^^^^^^^^^^^^^^^^^^^^^^^^^^^^^^^^^^^^^^^^^^^^^^^
  File "/home/airflow/.local/lib/python3.12/site-packages/airflow/models/taskinstance.py", line 432, in _execute_callable
    return execute_callable(context=context, **execute_callable_kwargs)
           ^^^^^^^^^^^^^^^^^^^^^^^^^^^^^^^^^^^^^^^^^^^^^^^^^^^^^^^^^^^^
  File "/home/airflow/.local/lib/python3.12/site-packages/airflow/models/baseoperator.py", line 401, in wrapper
    return func(self, *args, **kwargs)
           ^^^^^^^^^^^^^^^^^^^^^^^^^^^
  File "/home/airflow/.local/lib/python3.12/site-packages/airflow/operators/python.py", line 235, in execute
    return_value = self.execute_callable()
                   ^^^^^^^^^^^^^^^^^^^^^^^
  File "/home/airflow/.local/lib/python3.12/site-packages/airflow/operators/python.py", line 252, in execute_callable
    return self.python_callable(*self.op_args, **self.op_kwargs)
           ^^^^^^^^^^^^^^^^^^^^^^^^^^^^^^^^^^^^^^^^^^^^^^^^^^^^^
  File "/opt/airflow/dags/dag.py", line 86, in etl_task
    df = transform_data(file_suffix)
         ^^^^^^^^^^^^^^^^^^^^^^^^^^^
  File "/opt/airflow/dags/dag.py", line 51, in transform_data
    s3_input_path = get_latest_s3_file(S3_BUCKET_NAME, file_suffix)
                    ^^^^^^^^^^^^^^^^^^^^^^^^^^^^^^^^^^^^^^^^^^^^^^^
  File "/opt/airflow/dags/dag.py", line 29, in get_latest_s3_file
    response = s3.list_objects_v2(Bucket=bucket_name)
               ^^^^^^^^^^^^^^^^^^^^^^^^^^^^^^^^^^^^^^
  File "/home/airflow/.local/lib/python3.12/site-packages/botocore/client.py", line 565, in _api_call
    return self._make_api_call(operation_name, kwargs)
           ^^^^^^^^^^^^^^^^^^^^^^^^^^^^^^^^^^^^^^^^^^^
  File "/home/airflow/.local/lib/python3.12/site-packages/botocore/client.py", line 1001, in _make_api_call
    http, parsed_response = self._make_request(
                            ^^^^^^^^^^^^^^^^^^^
  File "/home/airflow/.local/lib/python3.12/site-packages/botocore/client.py", line 1027, in _make_request
    return self._endpoint.make_request(operation_model, request_dict)
           ^^^^^^^^^^^^^^^^^^^^^^^^^^^^^^^^^^^^^^^^^^^^^^^^^^^^^^^^^^
  File "/home/airflow/.local/lib/python3.12/site-packages/botocore/endpoint.py", line 119, in make_request
    return self._send_request(request_dict, operation_model)
           ^^^^^^^^^^^^^^^^^^^^^^^^^^^^^^^^^^^^^^^^^^^^^^^^^
  File "/home/airflow/.local/lib/python3.12/site-packages/botocore/endpoint.py", line 198, in _send_request
    request = self.create_request(request_dict, operation_model)
              ^^^^^^^^^^^^^^^^^^^^^^^^^^^^^^^^^^^^^^^^^^^^^^^^^^
  File "/home/airflow/.local/lib/python3.12/site-packages/botocore/endpoint.py", line 134, in create_request
    self._event_emitter.emit(
  File "/home/airflow/.local/lib/python3.12/site-packages/botocore/hooks.py", line 412, in emit
    return self._emitter.emit(aliased_event_name, **kwargs)
           ^^^^^^^^^^^^^^^^^^^^^^^^^^^^^^^^^^^^^^^^^^^^^^^^
  File "/home/airflow/.local/lib/python3.12/site-packages/botocore/hooks.py", line 256, in emit
    return self._emit(event_name, kwargs)
           ^^^^^^^^^^^^^^^^^^^^^^^^^^^^^^
  File "/home/airflow/.local/lib/python3.12/site-packages/botocore/hooks.py", line 239, in _emit
    response = handler(**kwargs)
               ^^^^^^^^^^^^^^^^^
  File "/home/airflow/.local/lib/python3.12/site-packages/botocore/signers.py", line 105, in handler
    return self.sign(operation_name, request)
           ^^^^^^^^^^^^^^^^^^^^^^^^^^^^^^^^^^
  File "/home/airflow/.local/lib/python3.12/site-packages/botocore/signers.py", line 199, in sign
    auth.add_auth(request)
  File "/home/airflow/.local/lib/python3.12/site-packages/botocore/auth.py", line 418, in add_auth
    raise NoCredentialsError()
botocore.exceptions.NoCredentialsError: Unable to locate credentials
[2024-07-09T15:10:31.903+0000] {taskinstance.py:1206} INFO - Marking task as UP_FOR_RETRY. dag_id=etl_process, task_id=etl_products, run_id=scheduled__2024-07-08T00:00:00+00:00, execution_date=20240708T000000, start_date=20240709T151028, end_date=20240709T151031
[2024-07-09T15:10:31.942+0000] {standard_task_runner.py:110} ERROR - Failed to execute job 571 for task etl_products (Unable to locate credentials; 85909)
[2024-07-09T15:10:31.976+0000] {local_task_job_runner.py:240} INFO - Task exited with return code 1
[2024-07-09T15:10:32.007+0000] {taskinstance.py:3503} INFO - 0 downstream tasks scheduled from follow-on schedule check
[2024-07-09T15:10:32.011+0000] {local_task_job_runner.py:222} INFO - ::endgroup::
